Traceback (most recent call last):
  File "/home/saul/anaconda3/envs/OptimizationForML/lib/python3.9/site-packages/jupyter_cache/executors/utils.py", line 51, in single_nb_execution
    executenb(
  File "/home/saul/anaconda3/envs/OptimizationForML/lib/python3.9/site-packages/nbclient/client.py", line 1093, in execute
    return NotebookClient(nb=nb, resources=resources, km=km, **kwargs).execute()
  File "/home/saul/anaconda3/envs/OptimizationForML/lib/python3.9/site-packages/nbclient/util.py", line 84, in wrapped
    return just_run(coro(*args, **kwargs))
  File "/home/saul/anaconda3/envs/OptimizationForML/lib/python3.9/site-packages/nbclient/util.py", line 62, in just_run
    return loop.run_until_complete(coro)
  File "/home/saul/anaconda3/envs/OptimizationForML/lib/python3.9/asyncio/base_events.py", line 642, in run_until_complete
    return future.result()
  File "/home/saul/anaconda3/envs/OptimizationForML/lib/python3.9/site-packages/nbclient/client.py", line 559, in async_execute
    await self.async_execute_cell(
  File "/home/saul/anaconda3/envs/OptimizationForML/lib/python3.9/site-packages/nbclient/client.py", line 854, in async_execute_cell
    self._check_raise_for_error(cell, exec_reply)
  File "/home/saul/anaconda3/envs/OptimizationForML/lib/python3.9/site-packages/nbclient/client.py", line 756, in _check_raise_for_error
    raise CellExecutionError.from_cell_and_msg(cell, exec_reply_content)
nbclient.exceptions.CellExecutionError: An error occurred while executing the following cell:
------------------
np.hstack([a, b]) + v # does not work
------------------

[0;31m---------------------------------------------------------------------------[0m
[0;31mValueError[0m                                Traceback (most recent call last)
[0;32m/tmp/ipykernel_31344/11420762.py[0m in [0;36m<module>[0;34m[0m
[0;32m----> 1[0;31m [0mnp[0m[0;34m.[0m[0mhstack[0m[0;34m([0m[0;34m[[0m[0ma[0m[0;34m,[0m [0mb[0m[0;34m][0m[0;34m)[0m [0;34m+[0m [0mv[0m [0;31m# does not work[0m[0;34m[0m[0;34m[0m[0m
[0m
[0;31mValueError[0m: operands could not be broadcast together with shapes (2,4) (2,) 
ValueError: operands could not be broadcast together with shapes (2,4) (2,) 

